
IID partitioning:
60,000 samples randomly distributed to 100 clients

Test  0
Downloading data from https://storage.googleapis.com/tensorflow/tf-keras-datasets/mnist.npz
Traceback (most recent call last):
  File "/sw/arcts/centos7/python3.7-anaconda/2019.07/lib/python3.7/urllib/request.py", line 1317, in do_open
    encode_chunked=req.has_header('Transfer-encoding'))
  File "/sw/arcts/centos7/python3.7-anaconda/2019.07/lib/python3.7/http/client.py", line 1229, in request
    self._send_request(method, url, body, headers, encode_chunked)
  File "/sw/arcts/centos7/python3.7-anaconda/2019.07/lib/python3.7/http/client.py", line 1275, in _send_request
    self.endheaders(body, encode_chunked=encode_chunked)
  File "/sw/arcts/centos7/python3.7-anaconda/2019.07/lib/python3.7/http/client.py", line 1224, in endheaders
    self._send_output(message_body, encode_chunked=encode_chunked)
  File "/sw/arcts/centos7/python3.7-anaconda/2019.07/lib/python3.7/http/client.py", line 1016, in _send_output
    self.send(msg)
  File "/sw/arcts/centos7/python3.7-anaconda/2019.07/lib/python3.7/http/client.py", line 956, in send
    self.connect()
  File "/sw/arcts/centos7/python3.7-anaconda/2019.07/lib/python3.7/http/client.py", line 1384, in connect
    super().connect()
  File "/sw/arcts/centos7/python3.7-anaconda/2019.07/lib/python3.7/http/client.py", line 928, in connect
    (self.host,self.port), self.timeout, self.source_address)
  File "/sw/arcts/centos7/python3.7-anaconda/2019.07/lib/python3.7/socket.py", line 727, in create_connection
    raise err
  File "/sw/arcts/centos7/python3.7-anaconda/2019.07/lib/python3.7/socket.py", line 716, in create_connection
    sock.connect(sa)
OSError: [Errno 101] Network is unreachable

During handling of the above exception, another exception occurred:

Traceback (most recent call last):
  File "/home/apawlik/.local/lib/python3.7/site-packages/tensorflow_core/python/keras/utils/data_utils.py", line 251, in get_file
    urlretrieve(origin, fpath, dl_progress)
  File "/sw/arcts/centos7/python3.7-anaconda/2019.07/lib/python3.7/urllib/request.py", line 247, in urlretrieve
    with contextlib.closing(urlopen(url, data)) as fp:
  File "/sw/arcts/centos7/python3.7-anaconda/2019.07/lib/python3.7/urllib/request.py", line 222, in urlopen
    return opener.open(url, data, timeout)
  File "/sw/arcts/centos7/python3.7-anaconda/2019.07/lib/python3.7/urllib/request.py", line 525, in open
    response = self._open(req, data)
  File "/sw/arcts/centos7/python3.7-anaconda/2019.07/lib/python3.7/urllib/request.py", line 543, in _open
    '_open', req)
  File "/sw/arcts/centos7/python3.7-anaconda/2019.07/lib/python3.7/urllib/request.py", line 503, in _call_chain
    result = func(*args)
  File "/sw/arcts/centos7/python3.7-anaconda/2019.07/lib/python3.7/urllib/request.py", line 1360, in https_open
    context=self._context, check_hostname=self._check_hostname)
  File "/sw/arcts/centos7/python3.7-anaconda/2019.07/lib/python3.7/urllib/request.py", line 1319, in do_open
    raise URLError(err)
urllib.error.URLError: <urlopen error [Errno 101] Network is unreachable>

During handling of the above exception, another exception occurred:

Traceback (most recent call last):
  File "tff_main.py", line 11, in <module>
    partitioner.go(int(sys.argv[1]))
  File "/home/apawlik/federated/iid.py", line 21, in go
    (x_train, y_train) = self.load_data()
  File "/home/apawlik/federated/partitioner.py", line 99, in load_data
    (x_train, y_train), (x_trash, y_trash) = mnist.load_data()
  File "/home/apawlik/.local/lib/python3.7/site-packages/tensorflow_core/python/keras/datasets/mnist.py", line 50, in load_data
    '731c5ac602752760c8e48fbffcf8c3b850d9dc2a2aedcf2cc48468fc17b673d1')
  File "/home/apawlik/.local/lib/python3.7/site-packages/tensorflow_core/python/keras/utils/data_utils.py", line 255, in get_file
    raise Exception(error_msg.format(origin, e.errno, e.reason))
Exception: URL fetch failure on https://storage.googleapis.com/tensorflow/tf-keras-datasets/mnist.npz: None -- [Errno 101] Network is unreachable
